# try-catch文でエラーを処理する

前のセクションでエラーの種類について学びました。今度は、エラーが発生してもプログラムが停止しないようにする方法を学びましょう。これを「エラーハンドリング」と呼びます。

Dartでは、`try-catch文`を使用してエラーを優雅に処理することができます。まるで「もしエラーが起きたら、こう対処してね」という指示書を書くようなものです。

## try-catch文の基本構文

try-catch文の基本的な構文は次のとおりです：

```javascript
try {
  // エラーが発生する可能性のあるコード
} catch (e) {
  // エラーが発生した時の処理
}
```

実際の例を見てみましょう：

```javascript
void main() {
  try {
    List<int> numbers = [1, 2, 3];
    print(numbers[5]);  // 範囲外アクセス
  } catch (e) {
    print("エラーが発生しました: $e");
  }
  
  print("プログラムは続行されます");
}
```

**実行結果：**
```
エラーが発生しました: RangeError (index): Invalid value: Not in inclusive range 0..2: 5
プログラムは続行されます
```

なるほど！エラーが発生してもプログラムが停止せず、catch文の中の処理が実行されました。

## 具体的な例：安全な数値変換

ユーザーから入力された文字列を数値に変換する場合を考えてみましょう：

```javascript
void main() {
  String userInput = "abc";  // 数値に変換できない文字列
  
  try {
    int number = int.parse(userInput);
    print("変換された数値: $number");
  } catch (e) {
    print("数値に変換できませんでした: $userInput");
    print("有効な数値を入力してください");
  }
}
```

**実行結果：**
```
数値に変換できませんでした: abc
有効な数値を入力してください
```

## 複数の例外の処理

異なる種類のエラーに対して、それぞれ異なる処理を行いたい場合があります。その場合は、複数のcatch文を使用できます：

```javascript
void main() {
  try {
    // 様々なエラーが発生する可能性のあるコード
    List<String> items = [];
    String firstItem = items[0];  // 空のリストからアクセス
  } on RangeError {
    print("範囲外エラーです。リストが空か、インデックスが無効です。");
  } on StateError {
    print("状態エラーが発生しました。");
  } catch (e) {
    print("予期しないエラー: $e");
  }
}
```

## finally文：必ず実行される処理

エラーが発生してもしなくても、必ず実行したい処理がある場合は`finally文`を使用します：

```javascript
void main() {
  try {
    print("ファイルを開いています...");
    // ファイル処理のコード（エラーが発生するかもしれない）
    throw Exception("ファイルが見つかりません");
  } catch (e) {
    print("エラー: $e");
  } finally {
    print("ファイルをクローズしました");  // 必ず実行される
  }
}
```

**実行結果：**
```
ファイルを開いています...
エラー: Exception: ファイルが見つかりません
ファイルをクローズしました
```

## 実践例：計算機能の安全な実装

電卓アプリを作る時の除算機能を安全に実装してみましょう：

```javascript
double safeDivision(double a, double b) {
  try {
    if (b == 0) {
      throw ArgumentError("ゼロで割ることはできません");
    }
    return a / b;
  } catch (e) {
    print("計算エラー: $e");
    return 0.0;  // デフォルト値を返す
  }
}

void main() {
  print("10 ÷ 2 = ${safeDivision(10, 2)}");   // 正常なケース
  print("10 ÷ 0 = ${safeDivision(10, 0)}");   // エラーケース
  print("計算処理が完了しました");
}
```

**実行結果：**
```
10 ÷ 2 = 5.0
計算エラー: Invalid argument(s): ゼロで割ることはできません
10 ÷ 0 = 0.0
計算処理が完了しました
```

## カスタム例外の作成

独自のエラー型を作成することもできます：

```javascript
// カスタム例外クラスの定義
class InvalidAgeException implements Exception {
  final String message;
  InvalidAgeException(this.message);
  
  @override
  String toString() => "InvalidAgeException: $message";
}

// 年齢チェック関数
void checkAge(int age) {
  if (age < 0) {
    throw InvalidAgeException("年齢は0以上である必要があります");
  }
  if (age > 150) {
    throw InvalidAgeException("年齢は150以下である必要があります");
  }
  print("有効な年齢です: $age歳");
}

void main() {
  List<int> testAges = [25, -5, 200];
  
  for (int age in testAges) {
    try {
      checkAge(age);
    } on InvalidAgeException catch (e) {
      print("年齢エラー: ${e.message}");
    } catch (e) {
      print("予期しないエラー: $e");
    }
  }
}
```

**実行結果：**
```
有効な年齢です: 25歳
年齢エラー: 年齢は0以上である必要があります
年齢エラー: 年齢は150以下である必要があります
```

## rethrow：エラーの再スロー

エラーをキャッチして何らかの処理を行った後、そのエラーを再度投げたい場合は`rethrow`を使用します：

```javascript
void processData(String data) {
  try {
    // データ処理
    if (data.isEmpty) {
      throw ArgumentError("データが空です");
    }
    print("データを処理しました: $data");
  } catch (e) {
    print("ログに記録: $e");  // ログを記録
    rethrow;  // エラーを再度投げる
  }
}

void main() {
  try {
    processData("");
  } catch (e) {
    print("メイン関数でキャッチ: $e");
  }
}
```

**実行結果：**
```
ログに記録: Invalid argument(s): データが空です
メイン関数でキャッチ: Invalid argument(s): データが空です
```

## エラーハンドリングのベストプラクティス

### 1. 適切なエラーメッセージを提供する

```javascript
void validateEmail(String email) {
  try {
    if (!email.contains('@')) {
      throw FormatException("有効なメールアドレスではありません: @が含まれていません");
    }
    print("有効なメールアドレス: $email");
  } catch (e) {
    print("入力エラー: $e");
  }
}
```

### 2. エラーの詳細をログに記録する

```javascript
void saveUserData(Map<String, dynamic> userData) {
  try {
    // ユーザーデータの保存処理
    print("ユーザーデータを保存しました");
  } catch (e, stackTrace) {
    print("保存エラー: $e");
    print("スタックトレース: $stackTrace");
    // 実際のアプリではログファイルに記録
  }
}
```

### 3. 復旧可能なエラーには代替案を提供する

```javascript
String getConfigValue(String key, String defaultValue) {
  try {
    // 設定ファイルから値を読み取る（失敗する可能性）
    throw Exception("設定ファイルが見つかりません");
  } catch (e) {
    print("設定の読み取りに失敗、デフォルト値を使用: $defaultValue");
    return defaultValue;
  }
}
```

## なるほど！ポイント

try-catch文を使うことで、エラーが発生してもプログラムが突然停止することを防げます。これにより、ユーザーにとって使いやすいアプリケーションを作ることができます。

重要なのは、すべてのコードをtry-catchで囲むのではなく、本当にエラーが発生する可能性がある部分にのみ使用することです。また、エラーが発生した時には、適切なメッセージをユーザーに表示して、次にどうすべきかを案内することが大切です。

次のセクションでは、バグを見つけて修正するための「デバッグの基本技術」について学習します！
